<?xml version="1.0" encoding="UTF-8"?>
<testng-results skipped="0" failed="2" total="5" passed="3">
  <reporter-output>
  </reporter-output>
  <suite name="Default suite" duration-ms="48" started-at="2017-04-17T15:21:03Z" finished-at="2017-04-17T15:21:03Z">
    <groups>
    </groups>
    <test name="Default test" duration-ms="48" started-at="2017-04-17T15:21:03Z" finished-at="2017-04-17T15:21:03Z">
      <class name="testNGscript.RetryTestCase">
        <test-method status="PASS" signature="a()[pri:0, instance:testNGscript.RetryTestCase@6a2bcfcb]" name="a" duration-ms="16" started-at="2017-04-17T11:21:03Z" finished-at="2017-04-17T11:21:03Z">
          <reporter-output>
          </reporter-output>
        </test-method> <!-- a -->
        <test-method status="FAIL" signature="testGenX()[pri:0, instance:testNGscript.RetryTestCase@6a2bcfcb]" name="testGenX" duration-ms="0" started-at="2017-04-17T11:21:03Z" finished-at="2017-04-17T11:21:03Z">
          <exception class="java.lang.AssertionError">
            <message>
              <![CDATA[expected [4] but found [2]]]>
            </message>
            <full-stacktrace>
              <![CDATA[java.lang.AssertionError: expected [4] but found [2]
	at org.testng.Assert.fail(Assert.java:94)
	at org.testng.Assert.failNotEquals(Assert.java:494)
	at org.testng.Assert.assertEquals(Assert.java:123)
	at org.testng.Assert.assertEquals(Assert.java:370)
	at org.testng.Assert.assertEquals(Assert.java:380)
	at testNGscript.RetryTestCase.testGenX(RetryTestCase.java:30)
	at sun.reflect.NativeMethodAccessorImpl.invoke0(Native Method)
	at sun.reflect.NativeMethodAccessorImpl.invoke(Unknown Source)
	at sun.reflect.DelegatingMethodAccessorImpl.invoke(Unknown Source)
	at java.lang.reflect.Method.invoke(Unknown Source)
	at org.testng.internal.MethodInvocationHelper.invokeMethod(MethodInvocationHelper.java:84)
	at org.testng.internal.Invoker.invokeMethod(Invoker.java:714)
	at org.testng.internal.Invoker.invokeTestMethod(Invoker.java:901)
	at org.testng.internal.Invoker.invokeTestMethods(Invoker.java:1231)
	at org.testng.internal.TestMethodWorker.invokeTestMethods(TestMethodWorker.java:127)
	at org.testng.internal.TestMethodWorker.run(TestMethodWorker.java:111)
	at org.testng.TestRunner.privateRun(TestRunner.java:767)
	at org.testng.TestRunner.run(TestRunner.java:617)
	at org.testng.SuiteRunner.runTest(SuiteRunner.java:334)
	at org.testng.SuiteRunner.runSequentially(SuiteRunner.java:329)
	at org.testng.SuiteRunner.privateRun(SuiteRunner.java:291)
	at org.testng.SuiteRunner.run(SuiteRunner.java:240)
	at org.testng.SuiteRunnerWorker.runSuite(SuiteRunnerWorker.java:52)
	at org.testng.SuiteRunnerWorker.run(SuiteRunnerWorker.java:86)
	at org.testng.TestNG.runSuitesSequentially(TestNG.java:1224)
	at org.testng.TestNG.runSuitesLocally(TestNG.java:1149)
	at org.testng.TestNG.run(TestNG.java:1057)
	at org.testng.remote.AbstractRemoteTestNG.run(AbstractRemoteTestNG.java:132)
	at org.testng.remote.RemoteTestNG.initAndRun(RemoteTestNG.java:230)
	at org.testng.remote.RemoteTestNG.main(RemoteTestNG.java:76)
]]>
            </full-stacktrace>
          </exception> <!-- java.lang.AssertionError -->
          <reporter-output>
          </reporter-output>
        </test-method> <!-- testGenX -->
        <test-method status="PASS" signature="testGenX()[pri:0, instance:testNGscript.RetryTestCase@6a2bcfcb]" name="testGenX" duration-ms="16" started-at="2017-04-17T11:21:03Z" finished-at="2017-04-17T11:21:03Z">
          <reporter-output>
          </reporter-output>
        </test-method> <!-- testGenX -->
        <test-method status="FAIL" signature="testGenX()[pri:0, instance:testNGscript.RetryTestCase@6a2bcfcb]" name="testGenX" duration-ms="0" started-at="2017-04-17T11:21:03Z" finished-at="2017-04-17T11:21:03Z">
          <exception class="java.lang.AssertionError">
            <message>
              <![CDATA[expected [4] but found [3]]]>
            </message>
            <full-stacktrace>
              <![CDATA[java.lang.AssertionError: expected [4] but found [3]
	at org.testng.Assert.fail(Assert.java:94)
	at org.testng.Assert.failNotEquals(Assert.java:494)
	at org.testng.Assert.assertEquals(Assert.java:123)
	at org.testng.Assert.assertEquals(Assert.java:370)
	at org.testng.Assert.assertEquals(Assert.java:380)
	at testNGscript.RetryTestCase.testGenX(RetryTestCase.java:30)
	at sun.reflect.NativeMethodAccessorImpl.invoke0(Native Method)
	at sun.reflect.NativeMethodAccessorImpl.invoke(Unknown Source)
	at sun.reflect.DelegatingMethodAccessorImpl.invoke(Unknown Source)
	at java.lang.reflect.Method.invoke(Unknown Source)
	at org.testng.internal.MethodInvocationHelper.invokeMethod(MethodInvocationHelper.java:84)
	at org.testng.internal.Invoker.invokeMethod(Invoker.java:714)
	at org.testng.internal.Invoker.retryFailed(Invoker.java:1049)
	at org.testng.internal.Invoker.invokeTestMethods(Invoker.java:1254)
	at org.testng.internal.TestMethodWorker.invokeTestMethods(TestMethodWorker.java:127)
	at org.testng.internal.TestMethodWorker.run(TestMethodWorker.java:111)
	at org.testng.TestRunner.privateRun(TestRunner.java:767)
	at org.testng.TestRunner.run(TestRunner.java:617)
	at org.testng.SuiteRunner.runTest(SuiteRunner.java:334)
	at org.testng.SuiteRunner.runSequentially(SuiteRunner.java:329)
	at org.testng.SuiteRunner.privateRun(SuiteRunner.java:291)
	at org.testng.SuiteRunner.run(SuiteRunner.java:240)
	at org.testng.SuiteRunnerWorker.runSuite(SuiteRunnerWorker.java:52)
	at org.testng.SuiteRunnerWorker.run(SuiteRunnerWorker.java:86)
	at org.testng.TestNG.runSuitesSequentially(TestNG.java:1224)
	at org.testng.TestNG.runSuitesLocally(TestNG.java:1149)
	at org.testng.TestNG.run(TestNG.java:1057)
	at org.testng.remote.AbstractRemoteTestNG.run(AbstractRemoteTestNG.java:132)
	at org.testng.remote.RemoteTestNG.initAndRun(RemoteTestNG.java:230)
	at org.testng.remote.RemoteTestNG.main(RemoteTestNG.java:76)
]]>
            </full-stacktrace>
          </exception> <!-- java.lang.AssertionError -->
          <reporter-output>
          </reporter-output>
        </test-method> <!-- testGenX -->
        <test-method status="PASS" signature="z()[pri:0, instance:testNGscript.RetryTestCase@6a2bcfcb]" name="z" duration-ms="0" started-at="2017-04-17T11:21:03Z" finished-at="2017-04-17T11:21:03Z">
          <reporter-output>
          </reporter-output>
        </test-method> <!-- z -->
      </class> <!-- testNGscript.RetryTestCase -->
    </test> <!-- Default test -->
  </suite> <!-- Default suite -->
</testng-results>
